Workbook

Sheet instructions
B3: Welcome! We’re looking for your expert input in this short survey about what happens to PET plastic from beverage bottles in the Netherlands. There isn’t enough data on this, and we urgently need better information to help create models that support smart policies against plastic pollution. Instead of asking for exact numbers—which can be difficult to estimate—we’ll ask you to provide a lower and upper bound that includes all values you consider plausible or able-to-be-believed. The survey follows the journey of these plastics—from when people use them, all the way to when they break down into microplastics in the environment. A lot happens in between, so if you're knowledgeable about any of the topics listed below, we’d really value your help!
B7: If you are knowledgeable in one or more of these topics, please provide a short explanation of your expertise (1-2 sentences) for each relevant topic, and answer the corresponding questions.
B9: Topics | C9: Explanation | D9: Link to questions
B10: Plastic disposal behavior of consumers | D10: {=HYPERLINK(CELL("address",questions!$E$5), "Questions 1-8")} -> Questions 1-8
B11: Plastic waste collection and treatment | D11: {=HYPERLINK(CELL("address",questions!$E$35), "Questions 9-12")} -> Questions 9-12
B12: Plastic recycling | D12: {=HYPERLINK(CELL("address",questions!$E$50), "Questions 13-14")} -> Questions 13-14
B13: Wastewater treatment | D13: {=HYPERLINK(CELL("address",questions!$E$60), "Questions 15-21")} -> Questions 15-21
B14: Sewage sludge and compost application | D14: {=HYPERLINK(CELL("address",questions!$E$82), "Questions 22-24")} -> Questions 22-24
B15: Cleaning and dispersion of plastic litter | D15: {=HYPERLINK(CELL("address",questions!$E$93), "Questions 25-29")} -> Questions 25-29
B16: Plastic degradation in the environment | D16: {=HYPERLINK(CELL("address",questions!$E$112), "Questions 30-42")} -> Questions 30-42
B17: Biological uptake and dispersion of microplastics | D17: {=HYPERLINK(CELL("address",questions!$E$139), "Questions 43-49")} -> Questions 43-49
B18: Dispersion and degradation of plastic litter | D18: {=HYPERLINK(CELL("address",questions!$E$167), "Questions 50-53")} -> Questions 50-53
B22: How to answer the questions?
B26: Rules for all questions: 1. The largest value must be greater than or equal to the lowest value. 2. The best guess must be in between the lowest value and the largest value. Rules for questions with more than one row: 3. The sum of lowest plausible values must be less than or equal to 1. 4. The sum of largest plausible values must be larger than or equal to 1. | C26: Realistically, what do you think is the lowest plausible value? | D26: Realistically, what do you think is the largest plausible value? | E26: Valid and complete response
B27: Lost socks
B28: Questions 1 | E28: =E29 -> TRUE
B29: What percentage of socks were lost at home during laundry in 2024? | C29: 0.05 | D29: 0.1 | E29: =AND(C29>=0, C29<=D29, D29<=1) -> TRUE
B30: Question 2 | E30: =AND(E31,E32,E33,SUM(C31:C33)<=1,SUM(D31:D33)>=1) -> TRUE
B31: Of socks lost during laundry at home in 2024, what percentage ended up in the wrong person's closet? | C31: 0.5 | D31: 0.8 | E31: =AND(C31>=0, C31<=D31, D31<=1) -> TRUE
B32: What percentage ended up in waste? | C32: 0.3 | D32: 0.5 | E32: =AND(C32>=0, C32<=D32, D32<=1) -> TRUE
B33: What percentage ended up somewhere else? | C33: 0 | D33: 0.05 | E33: =AND(C33>=0, C33<=D33, D33<=1) -> TRUE
B37: How to visualize the questions?
B54: Glossary
B56: Terms | C56: Definitions
B57: Agricultural soil | C57: Soil actively used for farming, including crop cultivation and livestock grazing.
B58: Bare soil | C58: Exposed soil with minimal or no vegetation cover
B59: Beach | C59: Sandy or pebbly zone between land and a water body
B60: Biodegradation | C60: Degradation of plastics by microrganisms
B61: Dumping | C61: Discarding outside of a waste bin and away from the point of use to avoid the constraint of appropriate disposal which can be costly or time-consuming.
B62: Forest soil | C62: Soil found under forested areas
B63: Freshwater sediment | C63: Deposited particles at the bottom of rivers, lakes, or streams in freshwater systems.
B64: Grassland | C64: Soil in open areas dominated by grasses with minimal tree cover
B65: Inland water | C65: Bodies of water such as lakes, rivers, and streams located away from the coast.
B66: Microplastics | C66: Small plastic particulates below 5 mm in size and above 1 µm.
B67: Ocean | C67: Large saline body of water covering much of the Earth's surface
... B80: Wetland | C80: Water-saturated land with hydric soils and aquatic vegetation

Sheet questions
A1: {=HYPERLINK(CELL("address",instructions!A29), "Link to instructions")} -> Link to instructions
A2: Rules for all questions: 1. The largest value must be greater than or equal to the lowest value. 2. The best guess must be in between the lowest value and the largest value. Rules for questions with more than one row: 3. The sum of lowest plausible values must be less than or equal to 1. 4. The sum of largest plausible values must be larger than or equal to 1. | B2: Type | C2: From | D2: To | E2: Realistically, what do you think is the lowest plausible value? | F2: Realistically, what do you think is the largest plausible value? | G2: Is the sum of lower values less than or equal to 1? | H2: Is the sum of upper values greater than or equal to 1? | I2: Is everything filled out? | J2: Valid and complete response | K2: Space for comments
A3: Plastic disposal behavior of consumers
A4: Questions 1 | G4: =SUM(E5,E237)<=1.001 -> TRUE | H4: =SUM(F5,F237)>=0.999 -> TRUE | I4: =IF(COUNTBLANK(E5:F5)=0, TRUE, FALSE) -> TRUE | J4: =AND(G4,H4,I4) -> TRUE
A5: What percentage of consumer PET bottles was used on-the-go (used on the move in public spaces), rather than at home (used in homes, cafes, and restaurants) in the Netherlands in 2024? | B5: MFA | C5: Consumer bottles | D5: Consumer bottles on-the-go | E5: 0.34984463 | F5: 0.34984463 | G5: =G4 -> TRUE | H5: =H4 -> TRUE | I5: =I4 -> TRUE | J5: =J4 -> TRUE
A6: Question 2 | G6: =SUM(E7,E238)<=1.001 -> TRUE | H6: =SUM(F7,F238)>=0.999 -> TRUE | I6: =IF(COUNTBLANK(E7:F7)=0, TRUE, FALSE) -> TRUE | J6: =AND(G6,H6,I6) -> TRUE
A7: What percentage of on-the-go consumer PET bottles (used on the move in public spaces) was returned through the deposit-refund scheme in the Netherlands in 2024? | B7: MFA | C7: Consumer bottles on-the-go | D7: Deposit refund scheme | E7: 0.68 | F7: 0.68 | G7: =G6 -> TRUE | H7: =H6 -> TRUE | I7: =I6 -> TRUE | J7: =J6 -> TRUE
A8: Question 3 | G8: =SUM(E9,E239)<=1.001 -> TRUE | H8: =SUM(F9,F239)>=0.999 -> TRUE | I8: =IF(COUNTBLANK(E9:F9)=0, TRUE, FALSE) -> TRUE | J8: =AND(G8,H8,I8) -> TRUE
A9: What percentage of at-home consumer PET bottles (used in homes, cafes, and restaurants) was returned through the deposit-refund scheme in the Netherlands in 2024? | B9: MFA | C9: Consumer bottles at home | D9: Deposit refund scheme | E9: 0.68 | F9: 0.68 | G9: =G8 -> TRUE | H9: =H8 -> TRUE | I9: =I8 -> TRUE | J9: =J8 -> TRUE
A10: Question 4 | G10: =SUM(E11:E16)<=1.001 -> TRUE | H10: =SUM(F11:F16)>=0.999 -> TRUE | I10: =IF(COUNTBLANK(E11:F16)=0, TRUE, FALSE) -> TRUE | J10: =AND(G10,H10,I10) -> TRUE
A11: What percentage of on-the-go consumer PET bottles (used on the move in public spaces) that were not returned through the deposit-refund scheme, was collected as mixed waste in the Netherlands in 2024? | B11: MFA | C11: Consumer bottles on-the-go non-deposit | D11: Mixed waste collection | E11: 0.40280714 | F11: 0.40280714 | G11: =G10 -> TRUE | H11: =H10 -> TRUE | I11: =I10 -> TRUE | J11: =J10 -> TRUE
A12: What percentage was littered (uncollected) in residential areas? | B12: MFA | C12: Consumer bottles on-the-go non-deposit | D12: Litter (residential) | E12: 0.43013054 | F12: 0.43013054 | G12: =G11 -> TRUE | H12: =H11 -> TRUE | I12: =I11 -> TRUE | J12: =J11 -> TRUE
A13: What percentage was littered (uncollected) on roadsides or along roadsides, including e.g. gas stations and restaurants along roads? | B13: MFA | C13: Consumer bottles on-the-go non-deposit | D13: Litter (roads) | E13: 0.15129067 | F13: 0.15129067 | G13: =G12 -> TRUE | H13: =H12 -> TRUE | I13: =I12 -> TRUE | J13: =J12 -> TRUE
A14: What percentage was littered (uncollected) in nature? | B14: MFA | C14: Consumer bottles on-the-go non-deposit | D14: Litter (nature) | E14: 0.015749653 | F14: 0.015749653 | G14: =G13 -> TRUE | H14: =H13 -> TRUE | I14: =I13 -> TRUE | J14: =J13 -> TRUE
A15: What percentage was released as microplastics to outdoor air during use, e.g. due to wear and tear or when opening a bottle? | B15: MFA | C15: Consumer bottles on-the-go non-deposit | D15: Outdoor air (MP) | E15: 1.1e-05 | F15: 1.1e-05 | G15: =G14 -> TRUE | H15: =H14 -> TRUE | I15: =I14 -> TRUE | J15: =J14 -> TRUE
A16: What percentage was ingested as microplastics by humans? | B16: MFA | C16: Consumer bottles on-the-go non-deposit | D16: Human (intestines) | E16: 1.1e-05 | F16: 1.1e-05 | G16: =G15 -> TRUE | H16: =H15 -> TRUE | I16: =I15 -> TRUE | J16: =J15 -> TRUE
A17: Question 5 | G17: =SUM(E18:E24)<=1.001 -> TRUE | H17: =SUM(F18:F24)>=0.999 -> TRUE | I17: =IF(COUNTBLANK(E18:F24)=0, TRUE, FALSE) -> TRUE | J17: =AND(G17,H17,I17) -> TRUE
A18: What percentage of at-home consumer PET bottles (used in homes, cafes, and restaurants) that were not returned through the deposit-refund scheme, was disposed in mixed waste streams in the Netherlands in 2024? | B18: MFA | C18: Consumer bottles at home non-deposit | D18: Mixed waste collection | E18: 0.17730104 | F18: 0.17730104 | G18: =G17 -> TRUE | H18: =G17 -> TRUE | I18: =H17 -> TRUE | J18: =J17 -> TRUE
A19: What percentage was disposed in packaging-specific waste streams such as PMD? | B19: MFA | C19: Consumer bottles at home non-deposit | D19: Packaging collection | E19: 0.80240305 | F19: 0.80240305 | G19: =G18 -> TRUE | H19: =G18 -> TRUE | I19: =H18 -> TRUE | J19: =J18 -> TRUE
A20: What percentage was dumped, i.e. discarded outside of a waste bin and away from the point of use to avoid the constraint of appropriate disposal which can be costly or time-consuming? | B20: MFA | C20: Consumer bottles at home non-deposit | D20: Dumping | E20: 0.00041046992 | F20: 0.00041046992 | G20: =G19 -> TRUE | H20: =G19 -> TRUE | I20: =H19 -> TRUE | J20: =J19 -> TRUE
A21: What percentage ended up in large, central composting facilities? | B21: MFA | C21: Consumer bottles at home non-deposit | D21: Compost collection (large) | E21: 0.019828366 | F21: 0.019828366 | G21: =G20 -> TRUE | H21: =G20 -> TRUE | I21: =H20 -> TRUE | J21: =J20 -> TRUE
A22: What percentage was disposed of in small, private compost systems? | B22: MFA | C22: Consumer bottles at home non-deposit | D22: Compost collection (small) | E22: 3.5078315e-05 | F22: 3.5078315e-05 | G22: =G21 -> TRUE | H22: =G21 -> TRUE | I22: =H21 -> TRUE | J22: =J21 -> TRUE
A23: What percentage was released as microplastics to indoor air during use? | B23: MFA | C23: Consumer bottles at home non-deposit | D23: Indoor air (MP) | E23: 1.1e-05 | F23: 1.1e-05 | G23: =G22 -> TRUE | H23: =G22 -> TRUE | I23: =H22 -> TRUE | J23: =J22 -> TRUE
A24: What percentage was ingested as microplastics by humans? | B24: MFA | C24: Consumer bottles at home non-deposit | D24: Human (intestines) | E24: 1.1e-05 | F24: 1.1e-05 | G24: =G23 -> TRUE | H24: =G23 -> TRUE | I24: =H23 -> TRUE | J24: =J23 -> TRUE
A25: Question 6 | G25: =SUM(E26:E28)<=1.001 -> TRUE | H25: =SUM(F26:F28)>=0.999 -> TRUE | I25: =IF(COUNTBLANK(E26:F28)=0, TRUE, FALSE) -> TRUE | J25: =AND(G25,H25,I25) -> TRUE
A26: What percentage of at-home consumer PET bottles (used in homes, cafes, and restaurants) that were dumped, was dumped in residential areas in the Netherlands in 2024? | B26: MFA | C26: Dumping | D26: Litter (residential) | E26: 0.16093217 | F26: 0.16093217 | G26: =G25 -> TRUE | H26: =H25 -> TRUE | I26: =I25 -> TRUE | J26: =J25 -> TRUE
A27: What percentage was dumped on or near roads? | B27: MFA | C27: Dumping | D27: Litter (roads) | E27: 0.50714162 | F27: 0.50714162 | G27: =G26 -> TRUE | H27: =H26 -> TRUE | I27: =I26 -> TRUE | J27: =J26 -> TRUE
A28: What percentage was dumped in nature? | B28: MFA | C28: Dumping | D28: Litter (nature) | E28: 0.33192621 | F28: 0.33192621 | G28: =G27 -> TRUE | H28: =H27 -> TRUE | I28: =I27 -> TRUE | J28: =J27 -> TRUE
A29: Question 7 | G29: =SUM(E30,E246)<=1.001 -> TRUE | H29: =SUM(F30,F246)>=0.999 -> TRUE | I29: =IF(COUNTBLANK(E30:F30)=0, TRUE, FALSE) -> TRUE | J29: =AND(G29,H29,I29) -> TRUE
A30: What percentage of microplastics on floors in buildings were disposed to wastewater (e.g. through mopping) rather than to mixed waste (e.g. through vacuuming), in the Netherlands in 2024? | B30: MFA | C30: Floors (MP) | D30: Waste water (MP) | E30: 0.15101244 | F30: 0.15101244 | G30: =G29 -> TRUE | H30: =H29 -> TRUE | I30: =I29 -> TRUE | J30: =J29 -> TRUE
A31: Question 8 | G31: =SUM(E32,E236)<=1.001 -> TRUE | H31: =SUM(F32,F236)>=0.999 -> TRUE | I31: =IF(COUNTBLANK(E32:F32)=0, TRUE, FALSE) -> TRUE | J31: =AND(G31,H31,I31) -> TRUE
A32: What percentage of wastewater from cleaning floors (e.g. from mobbing) was treated by the wastewater treatment system (i.e. disposed down the drain), rather than disposed directly to subsurface soil (e.g. thrown outside), in the Netherlands in 2024? | B32: MFA | C32: Waste water (MP) | D32: WWT (MP) | E32: 0.89032993 | F32: 0.89032993 | G32: =G31 -> TRUE | H32: =H31 -> TRUE | I32: =I31 -> TRUE | J32: =J31 -> TRUE
A33: Plastic waste collection and treatment
A34: Question 9 | G34: =SUM(E35,E240)<=1.001 -> TRUE | H34: =SUM(F35,F240)>=0.999 -> TRUE | I34: =IF(COUNTBLANK(E35:F35)=0, TRUE, FALSE) -> TRUE | J34: =AND(G34,H34,I34) -> TRUE
A35: What percentage of consumer PET bottles disposed in packaging-specific waste streams such as PMD, was collected in the Netherlands in 2024? | B35: MFA | C35: Packaging collection | D35: Packaging collected | E35: 1 | F35: 1 | G35: =G34 -> TRUE | H35: =H34 -> TRUE | I35: =I34 -> TRUE | J35: =J34 -> TRUE
A36: Question 10 | G36: =SUM(E37:E40)<=1.001 -> TRUE | H36: =SUM(F37:F40)>=0.999 -> TRUE | I36: =IF(COUNTBLANK(E37:F40)=0, TRUE, FALSE) -> TRUE | J36: =AND(G36,H36,I36) -> TRUE
A37: What percentage of consumer PET bottles collected from packaging-specific waste streams such as PMD, was brought to a plastic recycling facility in the Netherlands in 2024? | B37: MFA | C37: Packaging collected | D37: Packaging recycling | E37: 0.33532722 | F37: 0.33532722 | G37: =G36 -> TRUE | H37: =H36 -> TRUE | I37: =I36 -> TRUE | J37: =J36 -> TRUE
A38: What percentage was incinerated? | B38: MFA | C38: Packaging collected | D38: Incineration | E38: 0.64543336 | F38: 0.64543336 | G38: =G37 -> TRUE | H38: =H37 -> TRUE | I38: =I37 -> TRUE | J38: =J37 -> TRUE
A39: What percentage was brought to a sanitary landfill, which has a landfill gas collection system? | B39: MFA | C39: Packaging collected | D39: Sanitary landfill | E39: 0.019239416 | F39: 0.019239416 | G39: =G38 -> TRUE | H39: =H38 -> TRUE | I39: =I38 -> TRUE | J39: =J38 -> TRUE
A40: What percentage was lost to residential soil in the process of waste collection and transport? | B40: MFA | C40: Packaging collected | D40: Residential soil | E40: 0.0001 | F40: 0.0001 | G40: =G39 -> TRUE | H40: =H39 -> TRUE | I40: =I39 -> TRUE | J40: =J39 -> TRUE
...

Sheet list
A1: =TRUE -> TRUE
A2: =FALSE -> FALSE
